[2022-02-07 10:14:01,920] {taskinstance.py:851} INFO - Dependencies all met for <TaskInstance: generate_data.generate_data 2022-02-07T10:13:58.782788+00:00 [queued]>
[2022-02-07 10:14:01,955] {taskinstance.py:851} INFO - Dependencies all met for <TaskInstance: generate_data.generate_data 2022-02-07T10:13:58.782788+00:00 [queued]>
[2022-02-07 10:14:01,956] {taskinstance.py:1042} INFO - 
--------------------------------------------------------------------------------
[2022-02-07 10:14:01,956] {taskinstance.py:1043} INFO - Starting attempt 1 of 1
[2022-02-07 10:14:01,956] {taskinstance.py:1044} INFO - 
--------------------------------------------------------------------------------
[2022-02-07 10:14:01,971] {taskinstance.py:1063} INFO - Executing <Task(PythonOperator): generate_data> on 2022-02-07T10:13:58.782788+00:00
[2022-02-07 10:14:01,976] {standard_task_runner.py:52} INFO - Started process 41 to run task
[2022-02-07 10:14:01,982] {standard_task_runner.py:76} INFO - Running: ['airflow', 'tasks', 'run', 'generate_data', 'generate_data', '2022-02-07T10:13:58.782788+00:00', '--job-id', '36', '--pool', 'default_pool', '--raw', '--subdir', 'DAGS_FOLDER/geanrate_data.py', '--cfg-path', '/tmp/tmpf0n9ze37', '--error-file', '/tmp/tmpipl1px9h']
[2022-02-07 10:14:01,983] {standard_task_runner.py:77} INFO - Job 36: Subtask generate_data
[2022-02-07 10:14:02,053] {logging_mixin.py:104} INFO - Running <TaskInstance: generate_data.generate_data 2022-02-07T10:13:58.782788+00:00 [running]> on host df917bbc0fa0
[2022-02-07 10:14:02,115] {taskinstance.py:1257} INFO - Exporting the following env vars:
AIRFLOW_CTX_DAG_OWNER=airflow
AIRFLOW_CTX_DAG_ID=generate_data
AIRFLOW_CTX_TASK_ID=generate_data
AIRFLOW_CTX_EXECUTION_DATE=2022-02-07T10:13:58.782788+00:00
AIRFLOW_CTX_DAG_RUN_ID=manual__2022-02-07T10:13:58.782788+00:00
[2022-02-07 10:14:02,152] {taskinstance.py:1455} ERROR - 'Variable my_iterator does not exist'
Traceback (most recent call last):
  File "/home/airflow/.local/lib/python3.6/site-packages/airflow/models/taskinstance.py", line 1112, in _run_raw_task
    self._prepare_and_execute_task_with_callbacks(context, task)
  File "/home/airflow/.local/lib/python3.6/site-packages/airflow/models/taskinstance.py", line 1285, in _prepare_and_execute_task_with_callbacks
    result = self._execute_task(context, task_copy)
  File "/home/airflow/.local/lib/python3.6/site-packages/airflow/models/taskinstance.py", line 1315, in _execute_task
    result = task_copy.execute(context=context)
  File "/home/airflow/.local/lib/python3.6/site-packages/airflow/operators/python.py", line 117, in execute
    return_value = self.execute_callable()
  File "/home/airflow/.local/lib/python3.6/site-packages/airflow/operators/python.py", line 128, in execute_callable
    return self.python_callable(*self.op_args, **self.op_kwargs)
  File "/opt/airflow/dags/geanrate_data.py", line 21, in generate_data
    n = int(Variable.get('my_iterator'))
  File "/home/airflow/.local/lib/python3.6/site-packages/airflow/models/variable.py", line 128, in get
    raise KeyError(f'Variable {key} does not exist')
KeyError: 'Variable my_iterator does not exist'
[2022-02-07 10:14:02,159] {taskinstance.py:1503} INFO - Marking task as FAILED. dag_id=generate_data, task_id=generate_data, execution_date=20220207T101358, start_date=20220207T101401, end_date=20220207T101402
[2022-02-07 10:14:02,197] {local_task_job.py:146} INFO - Task exited with return code 1
