[2022-02-07 10:13:57,247] {taskinstance.py:851} INFO - Dependencies all met for <TaskInstance: generate_data.generate_data 2022-02-06T00:00:00+00:00 [queued]>
[2022-02-07 10:13:57,272] {taskinstance.py:851} INFO - Dependencies all met for <TaskInstance: generate_data.generate_data 2022-02-06T00:00:00+00:00 [queued]>
[2022-02-07 10:13:57,273] {taskinstance.py:1042} INFO - 
--------------------------------------------------------------------------------
[2022-02-07 10:13:57,273] {taskinstance.py:1043} INFO - Starting attempt 1 of 1
[2022-02-07 10:13:57,273] {taskinstance.py:1044} INFO - 
--------------------------------------------------------------------------------
[2022-02-07 10:13:57,286] {taskinstance.py:1063} INFO - Executing <Task(PythonOperator): generate_data> on 2022-02-06T00:00:00+00:00
[2022-02-07 10:13:57,290] {standard_task_runner.py:52} INFO - Started process 39 to run task
[2022-02-07 10:13:57,296] {standard_task_runner.py:76} INFO - Running: ['airflow', 'tasks', 'run', 'generate_data', 'generate_data', '2022-02-06T00:00:00+00:00', '--job-id', '35', '--pool', 'default_pool', '--raw', '--subdir', 'DAGS_FOLDER/geanrate_data.py', '--cfg-path', '/tmp/tmp7jyi_a26', '--error-file', '/tmp/tmpx64jreoq']
[2022-02-07 10:13:57,296] {standard_task_runner.py:77} INFO - Job 35: Subtask generate_data
[2022-02-07 10:13:57,373] {logging_mixin.py:104} INFO - Running <TaskInstance: generate_data.generate_data 2022-02-06T00:00:00+00:00 [running]> on host df917bbc0fa0
[2022-02-07 10:13:57,436] {taskinstance.py:1257} INFO - Exporting the following env vars:
AIRFLOW_CTX_DAG_OWNER=airflow
AIRFLOW_CTX_DAG_ID=generate_data
AIRFLOW_CTX_TASK_ID=generate_data
AIRFLOW_CTX_EXECUTION_DATE=2022-02-06T00:00:00+00:00
AIRFLOW_CTX_DAG_RUN_ID=scheduled__2022-02-06T00:00:00+00:00
[2022-02-07 10:13:57,527] {taskinstance.py:1455} ERROR - 'Variable my_iterator does not exist'
Traceback (most recent call last):
  File "/home/airflow/.local/lib/python3.6/site-packages/airflow/models/taskinstance.py", line 1112, in _run_raw_task
    self._prepare_and_execute_task_with_callbacks(context, task)
  File "/home/airflow/.local/lib/python3.6/site-packages/airflow/models/taskinstance.py", line 1285, in _prepare_and_execute_task_with_callbacks
    result = self._execute_task(context, task_copy)
  File "/home/airflow/.local/lib/python3.6/site-packages/airflow/models/taskinstance.py", line 1315, in _execute_task
    result = task_copy.execute(context=context)
  File "/home/airflow/.local/lib/python3.6/site-packages/airflow/operators/python.py", line 117, in execute
    return_value = self.execute_callable()
  File "/home/airflow/.local/lib/python3.6/site-packages/airflow/operators/python.py", line 128, in execute_callable
    return self.python_callable(*self.op_args, **self.op_kwargs)
  File "/opt/airflow/dags/geanrate_data.py", line 21, in generate_data
    n = int(Variable.get('my_iterator'))
  File "/home/airflow/.local/lib/python3.6/site-packages/airflow/models/variable.py", line 128, in get
    raise KeyError(f'Variable {key} does not exist')
KeyError: 'Variable my_iterator does not exist'
[2022-02-07 10:13:57,535] {taskinstance.py:1503} INFO - Marking task as FAILED. dag_id=generate_data, task_id=generate_data, execution_date=20220206T000000, start_date=20220207T101357, end_date=20220207T101357
[2022-02-07 10:13:57,631] {local_task_job.py:146} INFO - Task exited with return code 1
[2022-02-07 10:47:21,713] {taskinstance.py:851} INFO - Dependencies all met for <TaskInstance: generate_data.generate_data 2022-02-06T00:00:00+00:00 [queued]>
[2022-02-07 10:47:21,779] {taskinstance.py:851} INFO - Dependencies all met for <TaskInstance: generate_data.generate_data 2022-02-06T00:00:00+00:00 [queued]>
[2022-02-07 10:47:21,780] {taskinstance.py:1042} INFO - 
--------------------------------------------------------------------------------
[2022-02-07 10:47:21,780] {taskinstance.py:1043} INFO - Starting attempt 1 of 1
[2022-02-07 10:47:21,781] {taskinstance.py:1044} INFO - 
--------------------------------------------------------------------------------
[2022-02-07 10:47:21,810] {taskinstance.py:1063} INFO - Executing <Task(PythonOperator): generate_data> on 2022-02-06T00:00:00+00:00
[2022-02-07 10:47:21,829] {standard_task_runner.py:52} INFO - Started process 39 to run task
[2022-02-07 10:47:21,884] {standard_task_runner.py:76} INFO - Running: ['airflow', 'tasks', 'run', 'generate_data', 'generate_data', '2022-02-06T00:00:00+00:00', '--job-id', '2', '--pool', 'default_pool', '--raw', '--subdir', 'DAGS_FOLDER/geanrate_data.py', '--cfg-path', '/tmp/tmpw_0sbpos', '--error-file', '/tmp/tmp0caqi6kl']
[2022-02-07 10:47:21,889] {standard_task_runner.py:77} INFO - Job 2: Subtask generate_data
[2022-02-07 10:47:22,114] {logging_mixin.py:104} INFO - Running <TaskInstance: generate_data.generate_data 2022-02-06T00:00:00+00:00 [running]> on host 58930b363421
[2022-02-07 10:47:22,184] {taskinstance.py:1257} INFO - Exporting the following env vars:
AIRFLOW_CTX_DAG_OWNER=airflow
AIRFLOW_CTX_DAG_ID=generate_data
AIRFLOW_CTX_TASK_ID=generate_data
AIRFLOW_CTX_EXECUTION_DATE=2022-02-06T00:00:00+00:00
AIRFLOW_CTX_DAG_RUN_ID=scheduled__2022-02-06T00:00:00+00:00
[2022-02-07 10:47:22,290] {taskinstance.py:1455} ERROR - 'Variable my_iterator does not exist'
Traceback (most recent call last):
  File "/home/airflow/.local/lib/python3.6/site-packages/airflow/models/taskinstance.py", line 1112, in _run_raw_task
    self._prepare_and_execute_task_with_callbacks(context, task)
  File "/home/airflow/.local/lib/python3.6/site-packages/airflow/models/taskinstance.py", line 1285, in _prepare_and_execute_task_with_callbacks
    result = self._execute_task(context, task_copy)
  File "/home/airflow/.local/lib/python3.6/site-packages/airflow/models/taskinstance.py", line 1315, in _execute_task
    result = task_copy.execute(context=context)
  File "/home/airflow/.local/lib/python3.6/site-packages/airflow/operators/python.py", line 117, in execute
    return_value = self.execute_callable()
  File "/home/airflow/.local/lib/python3.6/site-packages/airflow/operators/python.py", line 128, in execute_callable
    return self.python_callable(*self.op_args, **self.op_kwargs)
  File "/opt/airflow/dags/geanrate_data.py", line 21, in generate_data
    n = int(Variable.get('my_iterator'))
  File "/home/airflow/.local/lib/python3.6/site-packages/airflow/models/variable.py", line 128, in get
    raise KeyError(f'Variable {key} does not exist')
KeyError: 'Variable my_iterator does not exist'
[2022-02-07 10:47:22,310] {taskinstance.py:1503} INFO - Marking task as FAILED. dag_id=generate_data, task_id=generate_data, execution_date=20220206T000000, start_date=20220207T104721, end_date=20220207T104722
[2022-02-07 10:47:22,445] {local_task_job.py:146} INFO - Task exited with return code 1
[2022-02-07 11:29:23,474] {taskinstance.py:851} INFO - Dependencies all met for <TaskInstance: generate_data.generate_data 2022-02-06T00:00:00+00:00 [queued]>
[2022-02-07 11:29:23,525] {taskinstance.py:851} INFO - Dependencies all met for <TaskInstance: generate_data.generate_data 2022-02-06T00:00:00+00:00 [queued]>
[2022-02-07 11:29:23,526] {taskinstance.py:1042} INFO - 
--------------------------------------------------------------------------------
[2022-02-07 11:29:23,527] {taskinstance.py:1043} INFO - Starting attempt 1 of 1
[2022-02-07 11:29:23,527] {taskinstance.py:1044} INFO - 
--------------------------------------------------------------------------------
[2022-02-07 11:29:23,564] {taskinstance.py:1063} INFO - Executing <Task(PythonOperator): generate_data> on 2022-02-06T00:00:00+00:00
[2022-02-07 11:29:23,570] {standard_task_runner.py:52} INFO - Started process 40 to run task
[2022-02-07 11:29:23,577] {standard_task_runner.py:76} INFO - Running: ['airflow', 'tasks', 'run', 'generate_data', 'generate_data', '2022-02-06T00:00:00+00:00', '--job-id', '2', '--pool', 'default_pool', '--raw', '--subdir', 'DAGS_FOLDER/geanrate_data.py', '--cfg-path', '/tmp/tmp89n0grz9', '--error-file', '/tmp/tmp06tw6ptf']
[2022-02-07 11:29:23,578] {standard_task_runner.py:77} INFO - Job 2: Subtask generate_data
[2022-02-07 11:29:23,662] {logging_mixin.py:104} INFO - Running <TaskInstance: generate_data.generate_data 2022-02-06T00:00:00+00:00 [running]> on host 6b2df22f9ed0
[2022-02-07 11:29:23,714] {taskinstance.py:1257} INFO - Exporting the following env vars:
AIRFLOW_CTX_DAG_OWNER=airflow
AIRFLOW_CTX_DAG_ID=generate_data
AIRFLOW_CTX_TASK_ID=generate_data
AIRFLOW_CTX_EXECUTION_DATE=2022-02-06T00:00:00+00:00
AIRFLOW_CTX_DAG_RUN_ID=scheduled__2022-02-06T00:00:00+00:00
[2022-02-07 11:29:29,479] {taskinstance.py:1455} ERROR - (_mysql_exceptions.OperationalError) (2006, "Can't connect to MySQL server on '192.168.1.5:3306' (111)")
(Background on this error at: http://sqlalche.me/e/13/e3q8)
Traceback (most recent call last):
  File "/home/airflow/.local/lib/python3.6/site-packages/sqlalchemy/engine/base.py", line 2336, in _wrap_pool_connect
    return fn()
  File "/home/airflow/.local/lib/python3.6/site-packages/sqlalchemy/pool/base.py", line 364, in connect
    return _ConnectionFairy._checkout(self)
  File "/home/airflow/.local/lib/python3.6/site-packages/sqlalchemy/pool/base.py", line 778, in _checkout
    fairy = _ConnectionRecord.checkout(pool)
  File "/home/airflow/.local/lib/python3.6/site-packages/sqlalchemy/pool/base.py", line 495, in checkout
    rec = pool._do_get()
  File "/home/airflow/.local/lib/python3.6/site-packages/sqlalchemy/pool/impl.py", line 140, in _do_get
    self._dec_overflow()
  File "/home/airflow/.local/lib/python3.6/site-packages/sqlalchemy/util/langhelpers.py", line 70, in __exit__
    with_traceback=exc_tb,
  File "/home/airflow/.local/lib/python3.6/site-packages/sqlalchemy/util/compat.py", line 182, in raise_
    raise exception
  File "/home/airflow/.local/lib/python3.6/site-packages/sqlalchemy/pool/impl.py", line 137, in _do_get
    return self._create_connection()
  File "/home/airflow/.local/lib/python3.6/site-packages/sqlalchemy/pool/base.py", line 309, in _create_connection
    return _ConnectionRecord(self)
  File "/home/airflow/.local/lib/python3.6/site-packages/sqlalchemy/pool/base.py", line 440, in __init__
    self.__connect(first_connect_check=True)
  File "/home/airflow/.local/lib/python3.6/site-packages/sqlalchemy/pool/base.py", line 661, in __connect
    pool.logger.debug("Error on connect(): %s", e)
  File "/home/airflow/.local/lib/python3.6/site-packages/sqlalchemy/util/langhelpers.py", line 70, in __exit__
    with_traceback=exc_tb,
  File "/home/airflow/.local/lib/python3.6/site-packages/sqlalchemy/util/compat.py", line 182, in raise_
    raise exception
  File "/home/airflow/.local/lib/python3.6/site-packages/sqlalchemy/pool/base.py", line 656, in __connect
    connection = pool._invoke_creator(self)
  File "/home/airflow/.local/lib/python3.6/site-packages/sqlalchemy/engine/strategies.py", line 114, in connect
    return dialect.connect(*cargs, **cparams)
  File "/home/airflow/.local/lib/python3.6/site-packages/sqlalchemy/engine/default.py", line 508, in connect
    return self.dbapi.connect(*cargs, **cparams)
  File "/home/airflow/.local/lib/python3.6/site-packages/MySQLdb/__init__.py", line 85, in Connect
    return Connection(*args, **kwargs)
  File "/home/airflow/.local/lib/python3.6/site-packages/MySQLdb/connections.py", line 208, in __init__
    super(Connection, self).__init__(*args, **kwargs2)
_mysql_exceptions.OperationalError: (2006, "Can't connect to MySQL server on '192.168.1.5:3306' (111)")

The above exception was the direct cause of the following exception:

Traceback (most recent call last):
  File "/home/airflow/.local/lib/python3.6/site-packages/airflow/models/taskinstance.py", line 1112, in _run_raw_task
    self._prepare_and_execute_task_with_callbacks(context, task)
  File "/home/airflow/.local/lib/python3.6/site-packages/airflow/models/taskinstance.py", line 1285, in _prepare_and_execute_task_with_callbacks
    result = self._execute_task(context, task_copy)
  File "/home/airflow/.local/lib/python3.6/site-packages/airflow/models/taskinstance.py", line 1315, in _execute_task
    result = task_copy.execute(context=context)
  File "/home/airflow/.local/lib/python3.6/site-packages/airflow/operators/python.py", line 117, in execute
    return_value = self.execute_callable()
  File "/home/airflow/.local/lib/python3.6/site-packages/airflow/operators/python.py", line 128, in execute_callable
    return self.python_callable(*self.op_args, **self.op_kwargs)
  File "/opt/airflow/dags/geanrate_data.py", line 29, in generate_data
    new_df.to_sql('raw_telecom',conn, if_exists='append')
  File "/home/airflow/.local/lib/python3.6/site-packages/pandas/core/generic.py", line 2615, in to_sql
    method=method,
  File "/home/airflow/.local/lib/python3.6/site-packages/pandas/io/sql.py", line 598, in to_sql
    method=method,
  File "/home/airflow/.local/lib/python3.6/site-packages/pandas/io/sql.py", line 1393, in to_sql
    table.create()
  File "/home/airflow/.local/lib/python3.6/site-packages/pandas/io/sql.py", line 721, in create
    if self.exists():
  File "/home/airflow/.local/lib/python3.6/site-packages/pandas/io/sql.py", line 708, in exists
    return self.pd_sql.has_table(self.name, self.schema)
  File "/home/airflow/.local/lib/python3.6/site-packages/pandas/io/sql.py", line 1431, in has_table
    self.connectable.dialect.has_table, name, schema or self.meta.schema
  File "/home/airflow/.local/lib/python3.6/site-packages/sqlalchemy/engine/base.py", line 2211, in run_callable
    with self._contextual_connect() as conn:
  File "/home/airflow/.local/lib/python3.6/site-packages/sqlalchemy/engine/base.py", line 2302, in _contextual_connect
    self._wrap_pool_connect(self.pool.connect, None),
  File "/home/airflow/.local/lib/python3.6/site-packages/sqlalchemy/engine/base.py", line 2340, in _wrap_pool_connect
    e, dialect, self
  File "/home/airflow/.local/lib/python3.6/site-packages/sqlalchemy/engine/base.py", line 1584, in _handle_dbapi_exception_noconnection
    sqlalchemy_exception, with_traceback=exc_info[2], from_=e
  File "/home/airflow/.local/lib/python3.6/site-packages/sqlalchemy/util/compat.py", line 182, in raise_
    raise exception
  File "/home/airflow/.local/lib/python3.6/site-packages/sqlalchemy/engine/base.py", line 2336, in _wrap_pool_connect
    return fn()
  File "/home/airflow/.local/lib/python3.6/site-packages/sqlalchemy/pool/base.py", line 364, in connect
    return _ConnectionFairy._checkout(self)
  File "/home/airflow/.local/lib/python3.6/site-packages/sqlalchemy/pool/base.py", line 778, in _checkout
    fairy = _ConnectionRecord.checkout(pool)
  File "/home/airflow/.local/lib/python3.6/site-packages/sqlalchemy/pool/base.py", line 495, in checkout
    rec = pool._do_get()
  File "/home/airflow/.local/lib/python3.6/site-packages/sqlalchemy/pool/impl.py", line 140, in _do_get
    self._dec_overflow()
  File "/home/airflow/.local/lib/python3.6/site-packages/sqlalchemy/util/langhelpers.py", line 70, in __exit__
    with_traceback=exc_tb,
  File "/home/airflow/.local/lib/python3.6/site-packages/sqlalchemy/util/compat.py", line 182, in raise_
    raise exception
  File "/home/airflow/.local/lib/python3.6/site-packages/sqlalchemy/pool/impl.py", line 137, in _do_get
    return self._create_connection()
  File "/home/airflow/.local/lib/python3.6/site-packages/sqlalchemy/pool/base.py", line 309, in _create_connection
    return _ConnectionRecord(self)
  File "/home/airflow/.local/lib/python3.6/site-packages/sqlalchemy/pool/base.py", line 440, in __init__
    self.__connect(first_connect_check=True)
  File "/home/airflow/.local/lib/python3.6/site-packages/sqlalchemy/pool/base.py", line 661, in __connect
    pool.logger.debug("Error on connect(): %s", e)
  File "/home/airflow/.local/lib/python3.6/site-packages/sqlalchemy/util/langhelpers.py", line 70, in __exit__
    with_traceback=exc_tb,
  File "/home/airflow/.local/lib/python3.6/site-packages/sqlalchemy/util/compat.py", line 182, in raise_
    raise exception
  File "/home/airflow/.local/lib/python3.6/site-packages/sqlalchemy/pool/base.py", line 656, in __connect
    connection = pool._invoke_creator(self)
  File "/home/airflow/.local/lib/python3.6/site-packages/sqlalchemy/engine/strategies.py", line 114, in connect
    return dialect.connect(*cargs, **cparams)
  File "/home/airflow/.local/lib/python3.6/site-packages/sqlalchemy/engine/default.py", line 508, in connect
    return self.dbapi.connect(*cargs, **cparams)
  File "/home/airflow/.local/lib/python3.6/site-packages/MySQLdb/__init__.py", line 85, in Connect
    return Connection(*args, **kwargs)
  File "/home/airflow/.local/lib/python3.6/site-packages/MySQLdb/connections.py", line 208, in __init__
    super(Connection, self).__init__(*args, **kwargs2)
sqlalchemy.exc.OperationalError: (_mysql_exceptions.OperationalError) (2006, "Can't connect to MySQL server on '192.168.1.5:3306' (111)")
(Background on this error at: http://sqlalche.me/e/13/e3q8)
[2022-02-07 11:29:29,506] {taskinstance.py:1503} INFO - Marking task as FAILED. dag_id=generate_data, task_id=generate_data, execution_date=20220206T000000, start_date=20220207T112923, end_date=20220207T112929
[2022-02-07 11:29:29,684] {local_task_job.py:146} INFO - Task exited with return code 1
